<?xml version="1.0" ?>
<robot name="arm" >
  <gazebo>
    <plugin filename="libgazebo_ros_control.so" name="ros_control" />
  </gazebo>

  <link name="world"/>

  <joint name="base_join" type="fixed">
    <parent link="world"/>
    <child link="base_link"/>
    <origin rpy="3.14159265 0.0 0.0" xyz="2.5 6.0 4.0"/>
  </joint>
 
  <link name="base_link"/>

  <joint name="shoulder_join_1" type="revolute">
    <parent link="base_link"/>
    <child link="shoulder_link_1"/>
    <origin rpy="0.0 0.0 0.0" xyz="0.0 0.0 0.0"/>
    <axis xyz="0 0 1"/>
    <limit effort="150.0" lower="-3.14159265" upper="3.14159265" velocity="3.15"/>
    <dynamics damping="5.0" friction="1.0"/>
  </joint>

  <link name="shoulder_link_1">
    <visual>
      <geometry>
        <cylinder length="0.1" radius="0.4"/>
      </geometry>
    </visual>
    <collision>
      <geometry>
        <cylinder length="0.1" radius="0.4"/>
      </geometry>
    </collision>
    <inertial>
      <mass value="8.393"/>
      <inertia ixx="0.227" ixy="0.0" ixz="0.0" iyy="0.227" iyz="0.0" izz="0.015"/>
    </inertial>
  </link>

  <joint name="shoulder_join_2" type="revolute">
    <parent link="shoulder_link_1"/>
    <child link="shoulder_link_2"/>
    <origin rpy="1.570796325 0.0 0.0" xyz="0.0 0.0 0.0"/>
    <axis xyz="0 0 1"/>
    <limit effort="150.0" lower="0.0" upper="3.14159265" velocity="3.15"/>
    <dynamics damping="5.0" friction="1.0"/>
  </joint>

  <link name="shoulder_link_2">
    <visual>
      <geometry>
        <cylinder length="0.1" radius="0.4"/>
      </geometry>
    </visual>
    <collision>
      <geometry>
        <cylinder length="0.1" radius="0.4"/>
      </geometry>
    </collision>
    <inertial>
      <mass value="8.393"/>
      <inertia ixx="0.22689067591" ixy="0.0" ixz="0.0" iyy="0.22689067591" iyz="0.0" izz="0.0151074"/>
    </inertial>
  </link>

  <joint name="main_arm_join" type="prismatic">
    <parent link="shoulder_link_2"/>
    <child link="main_arm_link"/>
    <origin rpy="0.0 1.570796325 0.0" xyz="0.5 0.0 0.0"/>
    <axis xyz="0 0 1"/>
    <limit effort="150.0" lower="0.0" upper="1" velocity="2"/>
    <dynamics damping="5.0" friction="1.0"/>
  </joint>

  <link name="main_arm_link">
    <visual>
      <geometry>
        <box size="0.1 0.1 7"/>
      </geometry>
      <origin rpy="0 0 0" xyz="0.0 0.0 -3.5"/>
    </visual>
    <collision>
      <geometry>
        <box size="0.1 0.1 7"/>
      </geometry>
      <origin rpy="0 0 0" xyz="0.0 0.0 -3.5"/>
    </collision>
    <inertial>
      <mass value="2.275"/>
      <origin rpy="0 0 0" xyz="0.0 0.0 -3.5"/>
      <inertia ixx="0.049443313556" ixy="0.0" ixz="0.0" iyy="0.049443313556" iyz="0.0" izz="0.004095"/>
    </inertial>
  </link>

  <joint name="elbow_join_1" type="revolute">
    <parent link="main_arm_link"/>
    <child link="elbow_link"/>
    <origin rpy="-1.570796325 0.0 0.0" xyz="0.0 0.0 0.0"/>
    <axis xyz="0 0 1"/>
    <limit effort="28.0" lower="-3.14159265" upper="3.14159265" velocity="3.2"/>
    <dynamics damping="5.0" friction="1.0"/>
  </joint>

  <link name="elbow_link">
    <visual>
      <geometry>
          <sphere radius="0.12"/>
      </geometry>
    </visual>
    <collision>
      <geometry>
          <sphere radius="0.12"/>
      </geometry>
    </collision>
    <inertial>
      <mass value="1.219"/>
      <origin rpy="0 0 0" xyz="0.0 0.0 0.0"/>
      <inertia ixx="0.111172755531" ixy="0.0" ixz="0.0" iyy="0.111172755531" iyz="0.0" izz="0.21942"/>
    </inertial>
  </link>

  <joint name="elbow_join_2" type="revolute">
    <parent link="elbow_link"/>
    <child link="secondary_arm_link"/>
    <origin rpy="0.0 -1.570796325 0.0" xyz="0.0 0.0 0.0"/>
    <axis xyz="0 0 1"/>
    <limit effort="28.0" lower="-1.570796325" upper="1.570796325" velocity="3.2"/>
    <dynamics damping="5.0" friction="1.0"/>
  </joint>

  <link name="secondary_arm_link">
    <visual>
      <geometry>
        <box size="3.2 0.07 0.07"/>
      </geometry>
      <origin rpy="0 0 0" xyz="1.4 0.0 0.0"/>
    </visual>
    <collision>
      <geometry>
        <box size="3.2 0.07 0.07"/>
      </geometry>
      <origin rpy="0 0 0" xyz="1.4 0.0 0.0"/>
    </collision>
    <inertial>
      <mass value="1.219"/>
      <origin rpy="0 0 0" xyz="1.4 0.0 0.0"/>
      <inertia ixx="0.111172755531" ixy="0.0" ixz="0.0" iyy="0.111172755531" iyz="0.0" izz="0.21942"/>
    </inertial>
  </link>

  <joint name="second_last_join" type="fixed">
    <parent link="secondary_arm_link"/>
    <child link="third_arm_link"/>
    <origin rpy="0.0 0.0 -1.570796325" xyz="3.0 0.0 0.0"/>
  </joint>

  <link name="third_arm_link">
    <visual>
      <geometry>
        <box size="0.2 0.05 0.05"/>
      </geometry>
      <origin rpy="0 0 0" xyz="0.1 0.0 0.0"/>
    </visual>
    <collision>
      <geometry>
        <box size="0.2 0.05 0.05"/>
      </geometry>
      <origin rpy="0 0 0" xyz="0.1 0.0 0.0"/>
    </collision>
    <inertial>
      <mass value="1.219"/>
      <origin rpy="0 0 0" xyz="0.1 0.0 0.0"/>
      <inertia ixx="0.111172755531" ixy="0.0" ixz="0.0" iyy="0.111172755531" iyz="0.0" izz="0.21942"/>
    </inertial>
  </link>

  <joint name="ee_join" type="fixed">
    <parent link="third_arm_link"/>
    <child link="ee_link"/>
    <origin rpy="0.0 0.0 0" xyz="0.2 0.0 0.0"/>
  </joint>

  <link name="ee_link">
    <visual>
      <geometry>
        <sphere radius="0.08"/>
      </geometry>
    </visual>
    <collision>
      <geometry>
        <sphere radius="0.08"/>
      </geometry>
    </collision>
    <inertial>
      <mass value="1.219"/>
      <inertia ixx="0.111172755531" ixy="0.0" ixz="0.0" iyy="0.111172755531" iyz="0.0" izz="0.21942"/>
    </inertial>
  </link>

</robot>
